Workbook
Name AWGList: 'WIRES (OPT)'!$A$3:$A$46
Name Magnets: 'MAGNETS (OPT)'!$A$3:$A$6
Name WindingList: 'MAGNETS (OPT)'!#REF!

Sheet Interface
A1: EGB241 EXCEL ASSIGNMENT INTERFACE FILE
A2: Group Details | D2: Status (Should be filled by Tutors):
A3: Group No.: | D3: Semester: | F3: Submission Date: | G3: DD/MM/YYYY
A4: Student Number | B4: First Name | D4: Last Name | F4: Contribution (Percent)
A10: INPUTS (Geometric Properties) | D10: INPUT (Magnetic Properties)
A11: Parameter | B11: Value | C11: Unit | D11: Parameter | F11: Value | G11: Unit
A12: Length of rotor (LR): | C12: mm | D12: Magent type:
A13: Radius of Windings (rave): | C13: mm | D13: Percent of flux leakage (FL): | F13: 0.5
A14: No. of Poles (p): | D14: INPUT (Electrical Properties)
A15: INPUTS (Winding Properties) | D15: Parameter | F15: Value | G15: Unit
A16: Parameter | B16: Value | C16: Unit | D16: Terminal Voltage (VT): | G16: V
A17: Winding Type: | D17: Degradation Factor (DF): | F17: 0.2
A18: Multiplex: | D18: OUTPUT (Intermediate Magnetic Properties)
A19: Maximum Current Density (J): | B19: 4 | C19: A/mm2 | D19: Parameter | F19: Value | G19: Unit
A20: Gauge of Wire (AWG): | D20: Flux density at surface (B): | G20: G
A21: No. of coils of rotor (C): | C21: ERROR CHECK | D21: Area of magnet surface (A): | G21: cm2
A22: No. of turns of wire per coil (Nc): | D22: Total flux of magnet (φTotal): | G22: mWb
A23: OUTPUT (Intermediate Winding Properties) | D23: Flux passing through rotor (φlinkage): | G23: mWb
A24: Parameter | B24: Value | C24: Unit | D24: OUTPUT (Intermediate Electromagnetic Properties)
A25: No. of conductors (Z): | D25: Parameter | F25: Value | G25: Unit
A26: No. of Parallel Paths (a): | D26: Motor Constant (K1):
A27: Winding Angle Lap (θw,L): | C27: Rad | D27: Motor Constant (K2): | G27: 1/Rad
A28: Winding Angle Wave (θw,w): | C28: Rad | D28: Resistance of Armature (Ra): | G28: W
A29: Chord Length (Lc): | C29: mm | D29: Maximum Armature Current (Ia,max): | G29: A
A30: Length of 1 turn (LW1): | C30: mm | D30: OUTPUT (Final Electromagnetic Properties)
A31: Length of 1 coil: | C31: mm | D31: Parameter | F31: Value | G31: Unit
A32: Length of all coils (LW): | C32: m (< 45 m) | D32: Maximum Rotational Speed (nr,max): | G32: rpm
A33: Cross section of coils inside slot: | C33: mm2 | D33: Rotational Speed at Max Torque (nr,fl): | G33: rpm
A34: Available Components | D34: Rotational Speed at Max Torque (wr,fl): | G34: Rad/sec
A35: Permanent Magnets: | B35: #2522, #3495, #3460, #3470, LM1614 | D35: Maximum Generated Torque (Tmax): | G35: Nm
A36: Wiress (AWG): | B36: 18 - 29 | D36: Maximum Produced Power (Pmax): | G36: W
A37: Permissible Length of Wire: | B37: 45 m | D37: Motor may actually produce (Pact): | G37: W
A38: Rotor Laminations (slots / thickness): | B38: (5 / 1 mm), (6 / 1 mm), (8 / 1.2 mm) | D38: Input Power (Pin): | G38: W
A39: Rotor Laminations (rmin,rmax): | B39: (15 mm, 30 mm) | D39: Efficiency:
A40: Number of Laminations per kit: | B40: 16 | D40: MARKED BY:
A41: ASSESSMENT FLAGS: | B41: CORRECT | C41: WRONG

Sheet Group 20 Sheet
B1: EGB241 EXCEL ASSIGNMENT INTERFACE FILE
B2: Group Details | E2: Status (Should be filled by Tutors):
B3: Group No.: | C3: 20 | E3: Semester: | F3: 1 | G3: Submission Date: | H3: DD/MM/YYYY
A4: Members | B4: Student Number | C4: First Name | E4: Last Name | G4: Contribution (Percent)
B5: n12455466 | C5: Krystian | E5: Rozanski
B6: n12466255 | C6: Darcy | E6: Sheppard
B7: n12427462 | C7: Paddy | E7: Dale | J7: Design aspects
B8: n12175048 | C8: Jakob | E8: Sahlberg | J8: Coupling
B9: n12363618 | C9: Jamie | E9: Fowler | J9: Brush
A10: Input and Output Properties | B10: INPUTS (Geometric Properties) | E10: INPUT (Magnetic Properties) | J10: Shaft
B11: Parameter | C11: Value | D11: Unit | E11: Parameter | G11: Value | H11: Unit | J11: Laminations
B12: Length of rotor (LR): | C12: =16*D63 -> 19.2 | D12: mm | E12: Magent type: | G12: #3495 | J12: Frame
B13: Radius of Windings (rave): | C13: =(E63-F63)/2 + F63 -> 22.5 | D13: mm | E13: Percent of flux leakage (FL): | G13: 0.5 | J13: Commutator (design well, research ideal)
B14: No. of Poles (p): | C14: 2 | E14: INPUT (Electrical Properties)
B15: INPUTS (Winding Properties) | E15: Parameter | G15: Value | H15: Unit
B16: Parameter | C16: Value | D16: Unit | E16: Terminal Voltage (VT): | G16: 1.78 | H16: V | I16: Pick Vt to ensure I<5A and nm<2000RPM
B17: Winding Type: | C17: Lap Wound | E17: Degradation Factor (DF): | G17: 0.2
B18: Multiplex: | C18: 1 | E18: OUTPUT (Intermediate Magnetic Properties) | J18: Notes
B19: Maximum Current Density (J): | C19: 4 | D19: A/mm2 | E19: Parameter | G19: Value | H19: Unit | J19: Inputs geometric
B20: Gauge of Wire (AWG): | C20: 29 | E20: Flux density at surface (B): | G20: =C54 -> 3709 | H20: G | I20: Lr | J20: 16 * thickness of slot (mm)
B21: No. of coils of rotor (C): | C21: 8 | D21: ERROR CHECK | E21: Area of magnet surface (A): | G21: =H54 -> 6 | H21: cm2 | I21: R ave | J21: (total radius-radius of slot)/2 + radius of slot
B22: No. of turns of wire per coil (Nc): | C22: 43 | E22: Total flux of magnet (φTotal): | G22: =(((G20/10000)*(G21/100^2))/(1+((0.001*(H54/100^2))/((G54/1000)*(C12*PI()*0.06*(160/360))))))*1000 -> 0.22252962 | H22: mWb | I22: chord length | J22: 2 * R ave sin(theta/2) , where theta =180 for full pitch
B23: OUTPUT (Intermediate Winding Properties) | E23: Flux passing through rotor (φlinkage): | G23: =G22*G13 -> 0.11126481 | H23: mWb | J23: therefore chord length 2* R ave
B24: Parameter | C24: Value | D24: Unit | E24: OUTPUT (Intermediate Electromagnetic Properties) | I24: length of 1 turn | J24: 2 * chord length + 2 length of roter
B25: No. of conductors (Z): | C25: =2*C21*C22 -> 688 | E25: Parameter | G25: Value | H25: Unit
B26: No. of Parallel Paths (a): | C26: =C18*C14 -> 2 | E26: Motor Constant (K1): | G26: =(C25*C14)/(60*C26) -> 11.466667
B27: Winding Angle Lap (θw,L): | C27: =PI() -> 3.1415927 | D27: Rad | E27: Motor Constant (K2): | G27: =(C25*C14)/(2*PI()*C26) -> 109.4986 | H27: 1/Rad | J27: flux total = Br*Am/(1+(lgAm/lmAg))
B28: Winding Angle Wave (θw,w): | C28: =PI() -> 3.1415927 | D28: Rad | E28: Resistance of Armature (Ra): | G28: =1+((I51/1000) *(C32/1000))/(4*4) -> 1.7412211 | H28: W | J28: aim for lg = 1mm
B29: Chord Length (Lc): | C29: =2*C13 -> 45 | D29: mm | E29: Maximum Armature Current (Ia,max): | G29: =G16/G28 -> 1.0222711 | H29: A | J29: Use circular pole guides with theta = 160 degrees
B30: Length of 1 turn (LW1): | C30: =2*C29+2*C12 -> 128.4 | D30: mm | E30: OUTPUT (Final Electromagnetic Properties) | J30: Ag = length of rotor * by circumfrence of rotor * 160/360
B31: Length of 1 coil: | C31: =C30*C22 -> 5521.2 | D31: mm | E31: Parameter | G31: Value | H31: Unit
B32: Length of all coils (LW): | C32: =C31*C21 -> 44169.6 | D32: m (< 45 m) | E32: Maximum Rotational Speed (nr,max): | G32: =G16/(G26*(G23/1000)) -> 1395.1631 | H32: rpm | J32: Resistance of Armature (Ra):
B33: Cross section of coils inside slot: | C33: =C22*0.823 -> 35.389 | D33: mm2 | E33: Rotational Speed at Max Torque (nr,fl): | G33: 0 | H33: rpm | J33: Is equal to 1 ohm for brushes + length of wire * resistance/m/4
B34: Available Components | E34: Rotational Speed at Max Torque (wr,fl): | G34: 0 | H34: Rad/sec
B35: Permanent Magnets: | C35: #2522, #3495, #3460, #3470, LM1614 | E35: Maximum Generated Torque (Tmax): | G35: =G27*(G23/1000)*G29 -> 0.012454678 | H35: Nm
B36: Wiress (AWG): | C36: 18 - 29 | E36: Maximum Produced Power (Pmax): | G36: =K39*K43 -> 0.45491064 | H36: W | J36: V supply (V terminal) = 2000 * k1 * flux linkage
B37: Permissible Length of Wire: | C37: 45 m | E37: Motor may actually produce (Pact): | G37: =K44*K39 -> 0.36392851 | H37: W | J37: Only torque is affected by degradation factor
B38: Rotor Laminations (slots / thickness): | C38: (5 / 1 mm), (6 / 1 mm), (8 / 1.2 mm) | E38: Input Power (Pin): | G38: =G16*K42 -> 0.90982127 | H38: W
B39: Rotor Laminations (rmin,rmax): | C39: (15 mm, 30 mm) | E39: Efficiency: | G39: =(G37/G38)*100 -> 40 | J39: angular freqeuncy = RPM / (30/pi) | K39: =K40/(30/PI()) -> 73.050568
B40: Number of Laminations per kit: | C40: 16 | E40: MARKED BY: | J40: P max at half terminal speed | K40: =G32/2 -> 697.58154
...

Sheet Input

Sheet Output without I lim

Sheet Output with I lim

Sheet MAGNETS (OPT)
A1: AVAILABLE MAGNETS
A2: CODE | B2: B (G) | C2: LENGTH (L) (mm) | D2: WIDTH (W) (mm) | E2: HEIGHT (mm) | F2: A (LxW) (cm2) | G2: PHI (mWb)
A3: #2522 | B3: 1400 | C3: 50 | D3: 20 | E3: 12.7 | F3: =(D3/10)*(C3/10) -> 10 | G3: =(B3/10000)*(F3/100^2)*1000 -> 0.14
A4: #3495 | B4: 3709 | C4: 40 | D4: 15 | E4: 8 | F4: =(D4/10)*(C4/10) -> 6 | G4: =(B4/10000)*(F4/100^2)*1000 -> 0.22254
A5: #3460 | B5: 2408 | C5: 25 | D5: 12.5 | E5: 3.5 | F5: =(D5/10)*(C5/10) -> 3.125 | G5: =(B5/10000)*(F5/100^2)*1000 -> 0.07525
A6: #3470 | B6: 3625 | C6: 25 | D6: 12.5 | E6: 6 | F6: =(D6/10)*(C6/10) -> 3.125 | G6: =(B6/10000)*(F6/100^2)*1000 -> 0.11328125
A7: LM1614 | B7: 580 | C7: 20 | D7: 15 | E7: 5 | F7: =(D7/10)*(C7/10) -> 3 | G7: =(B7/10000)*(F7/100^2)*1000 -> 0.0174
A8: By: Farzad Farajizadeh (20.04.2019)

Sheet WIRES (OPT)
A1: AWG | B1: Diameter | D1: Turns of wire, without insulation | F1: Area | H1: Resistance/Length | J1: Ia,max (A) = JxAxa
B2: (in) | C2: (mm) | D2: (per in) | E2: (per cm) | F2: (kcmil) | G2: (mm^2) | H2: mW/m | I2: mW/ft | L2: Refer to interface
A3: 0000 (4/0) | B3: 0.46 | C3: 11.684 | D3: 2.17 | E3: 0.856 | F3: 212 | G3: 107 | H3: 0.1608 | I3: 0.04901 | J3: =2*(4/1000^2)*(G3/1000^2) -> 8.56e-10 | L3: a=2
A4: 000 (3/0) | B4: 0.4096 | C4: 10.404 | D4: 2.44 | E4: 0.961 | F4: 168 | G4: 85 | H4: 0.2028 | I4: 0.0618 | J4: =2*(4/1000^2)*(G4/1000^2) -> 6.8e-10 | L4: J =4 | M4: per mm | N4: J=4/(1000^2) | P4: per m
A5: 00 (2/0) | B5: 0.3648 | C5: 9.266 | D5: 2.74 | E5: 1.08 | F5: 133 | G5: 67.4 | H5: 0.2557 | I5: 0.07793 | J5: =2*(4/1000^2)*(G5/1000^2) -> 5.392e-10
A6: 0 (1/0) | B6: 0.3249 | C6: 8.252 | D6: 3.08 | E6: 1.21 | F6: 106 | G6: 53.5 | H6: 0.3224 | I6: 0.09827 | J6: =2*(4/1000^2)*(G6/1000^2) -> 4.28e-10 | L6: Best current | O6: =MAX(J3:J46) -> 8.56e-10
A7: 1 | B7: 0.2893 | C7: 7.348 | D7: 3.46 | E7: 1.36 | F7: 83.7 | G7: 42.4 | H7: 0.4066 | I7: 0.1239 | J7: =2*(4/1000^2)*(G7/1000^2) -> 3.392e-10 | L7: Best current for selected AWG | O7: =MAX(J24:J35) -> 6.584e-12 | P7: AWG = 18
A8: 2 | B8: 0.2576 | C8: 6.544 | D8: 3.88 | E8: 1.53 | F8: 66.4 | G8: 33.6 | H8: 0.5127 | I8: 0.1563 | J8: =2*(4/1000^2)*(G8/1000^2) -> 2.688e-10
A9: 3 | B9: 0.2294 | C9: 5.827 | D9: 4.36 | E9: 1.72 | F9: 52.6 | G9: 26.7 | H9: 0.6465 | I9: 0.197 | J9: =2*(4/1000^2)*(G9/1000^2) -> 2.136e-10
A10: 4 | B10: 0.2043 | C10: 5.189 | D10: 4.89 | E10: 1.93 | F10: 41.7 | G10: 21.2 | H10: 0.8152 | I10: 0.2485 | J10: =2*(4/1000^2)*(G10/1000^2) -> 1.696e-10
A11: 5 | B11: 0.1819 | C11: 4.621 | D11: 5.5 | E11: 2.16 | F11: 33.1 | G11: 16.8 | H11: 1.028 | I11: 0.3133 | J11: =2*(4/1000^2)*(G11/1000^2) -> 1.344e-10
A12: 6 | B12: 0.162 | C12: 4.115 | D12: 6.17 | E12: 2.43 | F12: 26.3 | G12: 13.3 | H12: 1.296 | I12: 0.3951 | J12: =2*(4/1000^2)*(G12/1000^2) -> 1.064e-10
A13: 7 | B13: 0.1443 | C13: 3.665 | D13: 6.93 | E13: 2.73 | F13: 20.8 | G13: 10.5 | H13: 1.634 | I13: 0.4982 | J13: =2*(4/1000^2)*(G13/1000^2) -> 8.4e-11
A14: 8 | B14: 0.1285 | C14: 3.264 | D14: 7.78 | E14: 3.06 | F14: 16.5 | G14: 8.37 | H14: 2.061 | I14: 0.6282 | J14: =2*(4/1000^2)*(G14/1000^2) -> 6.696e-11
A15: 9 | B15: 0.1144 | C15: 2.906 | D15: 8.74 | E15: 3.44 | F15: 13.1 | G15: 6.63 | H15: 2.599 | I15: 0.7921 | J15: =2*(4/1000^2)*(G15/1000^2) -> 5.304e-11
A16: 10 | B16: 0.1019 | C16: 2.588 | D16: 9.81 | E16: 3.86 | F16: 10.4 | G16: 5.26 | H16: 3.277 | I16: 0.9989 | J16: =2*(4/1000^2)*(G16/1000^2) -> 4.208e-11
A17: 11 | B17: 0.0907 | C17: 2.305 | D17: 11 | E17: 4.34 | F17: 8.23 | G17: 4.17 | H17: 4.132 | I17: 1.26 | J17: =2*(4/1000^2)*(G17/1000^2) -> 3.336e-11
A18: 12 | B18: 0.0808 | C18: 2.053 | D18: 12.4 | E18: 4.87 | F18: 6.53 | G18: 3.31 | H18: 5.211 | I18: 1.588 | J18: =2*(4/1000^2)*(G18/1000^2) -> 2.648e-11
A19: 13 | B19: 0.072 | C19: 1.828 | D19: 13.9 | E19: 5.47 | F19: 5.18 | G19: 2.62 | H19: 6.571 | I19: 2.003 | J19: =2*(4/1000^2)*(G19/1000^2) -> 2.096e-11
... A46: 40 | B46: 0.00314 | C46: 0.0799 | D46: 318 | E46: 125 | F46: 0.00989 | G46: 0.00501 | H46: 3441 | I46: 1049 | J46: =2*(4/1000^2)*(G46/1000^2) -> 4.008e-14
A47: By: Farzad Farajizadeh (20.04.2019)
